Workbook

Sheet 1-Financial Model
B2: WaveCare Forecast
D3: 2027 | E3: 2028 | F3: 2029 | G3: 2030 | H3: 2031
B4: Assumptions | C4: Unit | D4: Year 1 | E4: Year 2 | F4: Year 3 | G4: Year 4 | H4: Year 5 | J4: Note
B5: Market Base
B6: Total Addressable Market | C6: # | D6: 1048 | E6: =D6*1.02 -> 1068.96 | F6: =E6*1.02 -> 1090.3392 | G6: =F6*1.02 -> 1112.146 | H6: =G6*1.02 -> 1134.3889 | J6: (1) Total Addressable Market (TAM) is expected to increased by 2% each year.
B7: Adoption rate | C7: % | D7: 0.005 | E7: 0.015 | F7: 0.035 | G7: 0.065 | H7: 0.1
B8: Total facilities | C8: # | D8: =INT(D6*D7) -> 5 | E8: =INT(E6*E7) -> 16 | F8: =INT(F6*F7) -> 38 | G8: =INT(G6*G7) -> 72 | H8: =INT(H6*H7) -> 113
B9: New facilities | C9: # | D9: =D8 -> 5 | E9: =E8-D8 -> 11 | F9: =F8-E8 -> 22 | G9: =G8-F8 -> 34 | H9: =H8-G8 -> 41
B10: Churn rate | C10: % | D10: 0 | E10: 0 | F10: 0.05 | G10: 0.05 | H10: 0.05
B11: Active facilities | C11: # | D11: =INT(D8) -> 5 | E11: =INT(E8) -> 16 | F11: =INT(F9+E11*(1-F10)) -> 37 | G11: =INT(G9+F11*(1-G10)) -> 69 | H11: =INT(H9+G11*(1-H10)) -> 106
B12: Residents per facility | C12: # | D12: 48 | E12: 48 | F12: 48 | G12: 48 | H12: 48
B14: Revenue Assumptions
B15: Hardware Revenue | C15: $ | D15: =(37*D12+280*3)*D9 -> 13080 | E15: =(37*E12+280*3)*E9 -> 28776 | F15: =(37*F12+280*3)*F9 -> 57552 | G15: =(37*G12+280*3)*G9 -> 88944 | H15: =(37*H12+280*3)*H9 -> 107256 | J15: (2) Wristband: US$ =37; Gateway: US$ =280$. Assumed that each facility needs 3 Gateways.
B16: Installation Revenue | C16: $ | D16: =D15*15% -> 1962 | E16: =E15*15% -> 4316.4 | F16: =F15*15% -> 8632.8 | G16: =G15*15% -> 13341.6 | H16: =H15*15% -> 16088.4
B17: Annual Service Revenue | C17: $ | D17: ='2-Monthly Service Revenue'!G18 -> 73125 | E17: ='2-Monthly Service Revenue'!G34 -> 295875 | F17: ='2-Monthly Service Revenue'!G50 -> 741816.06 | G17: ='2-Monthly Service Revenue'!G66 -> 1473820.7 | H17: ='2-Monthly Service Revenue'!G82 -> 2420309.8
B18: Total Revenue | C18: $ | D18: =SUM(D15:D17) -> 88167 | E18: =SUM(E15:E17) -> 328967.4 | F18: =SUM(F15:F17) -> 808000.86 | G18: =SUM(G15:G17) -> 1576106.3 | H18: =SUM(H15:H17) -> 2543654.2
B20: Cost Structure
B21: Variable
B22: Hardware COSG (per facility) | C22: $ | D22: =15*D12+120*3 -> 1080 | E22: =D22*103% -> 1112.4 | F22: =E22*103% -> 1145.772 | G22: =F22*103% -> 1180.1452 | H22: =G22*103% -> 1215.5495 | J22: (3) Wristband cost: US$ = 15; Gateway cost: US$ = 120. Assume that the cost of the Hardware COSG is affected by 3% inflation every year.
B23: Installation Cost (per facility) | C23: $ | D23: 300 | E23: =D23*103% -> 309 | F23: =E23*103% -> 318.27 | G23: =F23*103% -> 327.8181 | H23: =G23*103% -> 337.65264 | J23: (4) Assume that the cost of the Installation is affected by 3% inflation every year.
B24: Warranty Expense (variable portion) | C24: $ | D24: =D15*5% -> 654 | E24: =D24*103% -> 673.62 | F24: =E24*103% -> 693.8286 | G24: =F24*103% -> 714.64346 | H24: =G24*103% -> 736.08276 | J24: (5) Assume that 5% of Hardware Revenue is contributed to Warranty.
B25: Cloud Infrastructure (per resident) | C25: $ | D25: =0.5*12 -> 6 | E25: =D25*103% -> 6.18 | F25: =E25*103% -> 6.3654 | G25: =F25*103% -> 6.556362 | H25: =G25*103% -> 6.7530529 | J25: (6) Cloud Infrastructure: US$ = 0.5 per month per resident. Assume that the cost of the Cloud Infrastructure is affected by 3% inflation every year.
B26: Fixed
B27: Product R&D Cost | C27: $ | D27: 25000 | E27: =2%*E18 -> 6579.348 | F27: =2%*F18 -> 16160.017 | G27: =2%*G18 -> 31522.125 | H27: =2%*H18 -> 50873.084 | J27: (7) Coding cost is paid one-time to build Minimum Viable Product (MVP) at Y1. From Y2, 2% of Revenue is contributed to Product R&D.
B28: Certification & Compliance Cost | C28: $ | D28: 6500 | E28: 1500 | F28: 1500 | G28: 1500 | H28: 1500 | J28: (8) NCC, RoHS, IP67.
B29: Salaries & Commission | C29: $ | D29: ='3-Human Resource'!E24 -> 121308 | E29: ='3-Human Resource'!F24 -> 128877.6 | F29: ='3-Human Resource'!G24 -> 157900.2 | G29: ='3-Human Resource'!H24 -> 224212.65 | H29: ='3-Human Resource'!I24 -> 258688.88 | J29: (9) Assumptions are in Personel Sheet.
B30: Rent & Utilities | C30: $ | D30: =250*'3-Human Resource'!E13*12 -> 15000 | E30: =250*'3-Human Resource'!F13*12 -> 15000 | F30: =250*'3-Human Resource'!G13*12 -> 18000 | G30: =250*'3-Human Resource'!H13*12 -> 24000 | H30: =250*'3-Human Resource'!I13*12 -> 27000 | J30: (10) Assume that Co-working space/ Renting lab is US$250 per person per month. Utilities is included.
B31: Office supplies and Equipment | C31: $ | D31: =1500*'3-Human Resource'!E13+5000 -> 12500 | E31: =1500*('3-Human Resource'!F13-'3-Human Resource'!E13)+5000 -> 5000 | F31: =1500*('3-Human Resource'!G13-'3-Human Resource'!F13)+5000 -> 6500 | G31: =1500*('3-Human Resource'!H13-'3-Human Resource'!G13)+5000 -> 8000 | H31: =1500*('3-Human Resource'!I13-'3-Human Resource'!H13)+5000 -> 6500 | J31: (11) Assume that each employee needs 01 laptop (One-time: US$1500 per laptop) and annually US$5000 for other tools & equipments.
B32: Marketing & Campaigns | C32: $ | D32: 8000 | E32: =D32*105% -> 8400 | F32: =E32*105% -> 8820 | G32: =F32*105% -> 9261 | H32: =G32*105% -> 9724.05 | J32: (12) Marketing & Campaigns expenses is spent on 2 main expos annually (Medical Taiwan - Jun & Care Expo Taipei - Sep). Each expo is expected to have US$ 4000. The budget is raised 5% each year.
B33: Travel and Entertainment | C33: $ | D33: 5000 | E33: =D33*105% -> 5250 | F33: =E33*105% -> 5512.5 | G33: =F33*105% -> 5788.125 | H33: =G33*105% -> 6077.5312 | J33: (13) Travel and Entertainment is US$5000/ year. The budget is raised 5% each year.
B35: Tax Rate | C35: % | D35: 0.2 | E35: 0.2 | F35: 0.2 | G35: 0.2 | H35: 0.2
B37: Pro-Forma Income Statement
B38: Revenue | C38: $ | D38: =D18 -> 88167 | E38: =E18 -> 328967.4 | F38: =F18 -> 808000.86 | G38: =G18 -> 1576106.3 | H38: =H18 -> 2543654.2
B39: COGS | C39: $ | D39: =(D22*D11)+(D23*D11)+(D24)+(D25*D12*D11) -> 8994 | E39: =E22*E11+E23*E11+E24+E25*E12*E11 -> 28162.26 | F39: =F22*F11+F23*F11+F24+F25*F12*F11 -> 66168.333 | G39: =G22*G11+G23*G11+G24+G25*G12*G11 -> 126478.78 | H39: =H22*H11+H23*H11+H24+H25*H12*H11 -> 199735.04
B40: Gross Profit | C40: $ | D40: =D38-D39 -> 79173 | E40: =E38-E39 -> 300805.14 | F40: =F38-F39 -> 741832.53 | G40: =G38-G39 -> 1449627.5 | H40: =H38-H39 -> 2343919.1
B41: Gross Profit Margin | C41: % | D41: =D40/D38 -> 0.89798904 | E41: =E40/E38 -> 0.91439194 | F41: =F40/F38 -> 0.91810859 | G41: =G40/G38 -> 0.91975238 | H41: =H40/H38 -> 0.92147712
B43: Operating Expenses - OpEx
B44: R&D Expenses | C44: $
B45: Salaries - Engineer | C45: $ | D45: ='3-Human Resource'!E16+'3-Human Resource'!E17 -> 72000 | E45: ='3-Human Resource'!F16+'3-Human Resource'!F17 -> 75600 | F45: ='3-Human Resource'!G16+'3-Human Resource'!G17 -> 79380 | G45: ='3-Human Resource'!H16+'3-Human Resource'!H17 -> 125023.5 | H45: ='3-Human Resource'!I16+'3-Human Resource'!I17 -> 131274.67
B46: Product Research and Development | C46: $ | D46: =D27 -> 25000 | E46: =E27 -> 6579.348 | F46: =F27 -> 16160.017 | G46: =G27 -> 31522.125 | H46: =H27 -> 50873.084
...

Sheet 2-Monthly Service Revenue
B2: WaveCare Monthly Service Revenue Cohort Assumption
B3: Assumptions | C3: Active from Y-1 | D3: New Signed | E3: Churn Rate | F3: Cumulative Total Active | G3: Monthly service revenue
B4: Year 1
B5: Month
B6: Jan | C6: 0 | D6: ='1-Financial Model'!$D$9/12 -> 0.41666667 | E6: 0 | F6: =D6 -> 0.41666667 | G6: =F6*'1-Financial Model'!$D$12*30000/32*5% -> 937.5
B7: Feb | C7: 0 | D7: ='1-Financial Model'!$D$9/12 -> 0.41666667 | E7: 0 | F7: =C6+F6+D7 -> 0.83333333 | G7: =F7*'1-Financial Model'!$D$12*30000/32*5% -> 1875
B8: Mar | C8: 0 | D8: ='1-Financial Model'!$D$9/12 -> 0.41666667 | E8: 0 | F8: =C7+F7+D8 -> 1.25 | G8: =F8*'1-Financial Model'!$D$12*30000/32*5% -> 2812.5
B9: Apr | C9: 0 | D9: ='1-Financial Model'!$D$9/12 -> 0.41666667 | E9: 0 | F9: =C8+F8+D9 -> 1.6666667 | G9: =F9*'1-Financial Model'!$D$12*30000/32*5% -> 3750
B10: May | C10: 0 | D10: ='1-Financial Model'!$D$9/12 -> 0.41666667 | E10: 0 | F10: =C9+F9+D10 -> 2.0833333 | G10: =F10*'1-Financial Model'!$D$12*30000/32*5% -> 4687.5
B11: Jun | C11: 0 | D11: ='1-Financial Model'!$D$9/12 -> 0.41666667 | E11: 0 | F11: =C10+F10+D11 -> 2.5 | G11: =F11*'1-Financial Model'!$D$12*30000/32*5% -> 5625
B12: Jul | C12: 0 | D12: ='1-Financial Model'!$D$9/12 -> 0.41666667 | E12: 0 | F12: =C11+F11+D12 -> 2.9166667 | G12: =F12*'1-Financial Model'!$D$12*30000/32*5% -> 6562.5
B13: Aug | C13: 0 | D13: ='1-Financial Model'!$D$9/12 -> 0.41666667 | E13: 0 | F13: =C12+F12+D13 -> 3.3333333 | G13: =F13*'1-Financial Model'!$D$12*30000/32*5% -> 7500
B14: Sep | C14: 0 | D14: ='1-Financial Model'!$D$9/12 -> 0.41666667 | E14: 0 | F14: =C13+F13+D14 -> 3.75 | G14: =F14*'1-Financial Model'!$D$12*30000/32*5% -> 8437.5
B15: Oct | C15: 0 | D15: ='1-Financial Model'!$D$9/12 -> 0.41666667 | E15: 0 | F15: =C14+F14+D15 -> 4.1666667 | G15: =F15*'1-Financial Model'!$D$12*30000/32*5% -> 9375
B16: Nov | C16: 0 | D16: ='1-Financial Model'!$D$9/12 -> 0.41666667 | E16: 0 | F16: =C15+F15+D16 -> 4.5833333 | G16: =F16*'1-Financial Model'!$D$12*30000/32*5% -> 10312.5
B17: Dec | C17: 0 | D17: ='1-Financial Model'!$D$9/12 -> 0.41666667 | E17: 0 | F17: =C16+F16+D17 -> 5 | G17: =F17*'1-Financial Model'!$D$12*30000/32*5% -> 11250
B18: Total Year 1 | D18: =SUM(D6:D17) -> 5 | F18: =F17 -> 5 | G18: =SUM(G6:G17) -> 73125
B20: Year 2
B21: Month
B22: Jan | C22: =$D$18 -> 5 | D22: ='1-Financial Model'!$E$9/12 -> 0.91666667 | E22: 0 | F22: =C22+D22 -> 5.9166667 | G22: =F22*'1-Financial Model'!$D$12*30000/32*5% -> 13312.5
B23: Feb | C23: =$D$18 -> 5 | D23: ='1-Financial Model'!$E$9/12 -> 0.91666667 | E23: 0 | F23: =F22+D23 -> 6.8333333 | G23: =F23*'1-Financial Model'!$D$12*30000/32*5% -> 15375
B24: Mar | C24: =$D$18 -> 5 | D24: ='1-Financial Model'!$E$9/12 -> 0.91666667 | E24: 0 | F24: =F23+D24 -> 7.75 | G24: =F24*'1-Financial Model'!$D$12*30000/32*5% -> 17437.5
B25: Apr | C25: =$D$18 -> 5 | D25: ='1-Financial Model'!$E$9/12 -> 0.91666667 | E25: 0 | F25: =F24+D25 -> 8.6666667 | G25: =F25*'1-Financial Model'!$D$12*30000/32*5% -> 19500
B26: May | C26: =$D$18 -> 5 | D26: ='1-Financial Model'!$E$9/12 -> 0.91666667 | E26: 0 | F26: =F25+D26 -> 9.5833333 | G26: =F26*'1-Financial Model'!$D$12*30000/32*5% -> 21562.5
B27: Jun | C27: =$D$18 -> 5 | D27: ='1-Financial Model'!$E$9/12 -> 0.91666667 | E27: 0 | F27: =F26+D27 -> 10.5 | G27: =F27*'1-Financial Model'!$D$12*30000/32*5% -> 23625
B28: Jul | C28: =$D$18 -> 5 | D28: ='1-Financial Model'!$E$9/12 -> 0.91666667 | E28: 0 | F28: =F27+D28 -> 11.416667 | G28: =F28*'1-Financial Model'!$D$12*30000/32*5% -> 25687.5
B29: Aug | C29: =$D$18 -> 5 | D29: ='1-Financial Model'!$E$9/12 -> 0.91666667 | E29: 0 | F29: =F28+D29 -> 12.333333 | G29: =F29*'1-Financial Model'!$D$12*30000/32*5% -> 27750
B30: Sep | C30: =$D$18 -> 5 | D30: ='1-Financial Model'!$E$9/12 -> 0.91666667 | E30: 0 | F30: =F29+D30 -> 13.25 | G30: =F30*'1-Financial Model'!$D$12*30000/32*5% -> 29812.5
B31: Oct | C31: =$D$18 -> 5 | D31: ='1-Financial Model'!$E$9/12 -> 0.91666667 | E31: 0 | F31: =F30+D31 -> 14.166667 | G31: =F31*'1-Financial Model'!$D$12*30000/32*5% -> 31875
B32: Nov | C32: =$D$18 -> 5 | D32: ='1-Financial Model'!$E$9/12 -> 0.91666667 | E32: 0 | F32: =F31+D32 -> 15.083333 | G32: =F32*'1-Financial Model'!$D$12*30000/32*5% -> 33937.5
B33: Dec | C33: =$D$18 -> 5 | D33: ='1-Financial Model'!$E$9/12 -> 0.91666667 | E33: 0 | F33: =F32+D33 -> 16 | G33: =F33*'1-Financial Model'!$D$12*30000/32*5% -> 36000
B34: Total Year 2 | D34: =SUM(D22:D33)+C22 -> 16 | F34: =F33 -> 16 | G34: =SUM(G22:G33) -> 295875
B36: Year 3
B37: Month
B38: Jan | C38: =$D$34 -> 16 | D38: ='1-Financial Model'!$F$9/12 -> 1.8333333 | E38: =(1-'1-Financial Model'!$F$10)^(1/12)-1 -> -0.0042653188 | F38: =C38+D38+C38*E38 -> 17.765088 | G38: =F38*'1-Financial Model'!$D$12*30000/32*5% -> 39971.449
B39: Feb | C39: =$D$34+C38*E38 -> 15.931755 | D39: ='1-Financial Model'!$F$9/12 -> 1.8333333 | E39: =(1-'1-Financial Model'!$F$10)^(1/12)-1 -> -0.0042653188 | F39: =F38+D39+C39*E39 -> 19.530468 | G39: =F39*'1-Financial Model'!$D$12*30000/32*5% -> 43943.552
B40: Mar | C40: =$D$34+C39*E39 -> 15.932046 | D40: ='1-Financial Model'!$F$9/12 -> 1.8333333 | E40: =(1-'1-Financial Model'!$F$10)^(1/12)-1 -> -0.0042653188 | F40: =F39+D40+C40*E40 -> 21.295846 | G40: =F40*'1-Financial Model'!$D$12*30000/32*5% -> 47915.653
B41: Apr | C41: =$D$34+C40*E40 -> 15.932045 | D41: ='1-Financial Model'!$F$9/12 -> 1.8333333 | E41: =(1-'1-Financial Model'!$F$10)^(1/12)-1 -> -0.0042653188 | F41: =F40+D41+C41*E41 -> 23.061224 | G41: =F41*'1-Financial Model'!$D$12*30000/32*5% -> 51887.753
B42: May | C42: =$D$34+C41*E41 -> 15.932045 | D42: ='1-Financial Model'!$F$9/12 -> 1.8333333 | E42: =(1-'1-Financial Model'!$F$10)^(1/12)-1 -> -0.0042653188 | F42: =F41+D42+C42*E42 -> 24.826602 | G42: =F42*'1-Financial Model'!$D$12*30000/32*5% -> 55859.854
B43: Jun | C43: =$D$34+C42*E42 -> 15.932045 | D43: ='1-Financial Model'!$F$9/12 -> 1.8333333 | E43: =(1-'1-Financial Model'!$F$10)^(1/12)-1 -> -0.0042653188 | F43: =F42+D43+C43*E43 -> 26.59198 | G43: =F43*'1-Financial Model'!$D$12*30000/32*5% -> 59831.955
...

Sheet 3-Human Resource
B2: WaveCare Personel Forecast
E3: 2027 | F3: 2028 | G3: 2029 | H3: 2030 | I3: 2031
B4: Assumptions | C4: Unit | D4: Base Salary | E4: Year 1 | F4: Year 2 | G4: Year 3 | H4: Year 4 | I4: Year 5 | K4: Note
B5: Quantity Assumptions
B6: Engineer
B7: Firmware Engineer | C7: # | E7: 1 | F7: 1 | G7: 1 | H7: 1 | I7: 1
B8: Backend Engineer | C8: # | E8: 1 | F8: 1 | G8: 1 | H8: 2 | I8: 2
B9: Business Development
B10: Business Development Employee | C10: # | E10: 2 | F10: 2 | G10: 3 | H10: 3 | I10: 4 | K10: (1) Commission is based on 5% revenue of the Hardware.
B11: Admin/ Support
B12: Customer Support Employee | C12: # | E12: 1 | F12: 1 | G12: 1 | H12: 2 | I12: 2
B13: Total | C13: # | E13: =SUM(E7:E12) -> 5 | F13: =SUM(F7:F12) -> 5 | G13: =SUM(G7:G12) -> 6 | H13: =SUM(H7:H12) -> 8 | I13: =SUM(I7:I12) -> 9
B14: Salaries
B15: Engineer
B16: Firmware Engineer ($3000 per month) | C16: $ | D16: 3000 | E16: =D16*E7*12 -> 36000 | F16: =E16*105%/E7*F7 -> 37800 | G16: =F16*105%/F7*G7 -> 39690 | H16: =G16*105%/G7*H7 -> 41674.5 | I16: =H16*105%/H7*I7 -> 43758.225 | K16: (2) Assume that Salary Increase Rate is 5% annually.
B17: Backend Engineer ($3000 per month) | C17: $ | D17: 3000 | E17: =D17*E8*12 -> 36000 | F17: =E17*105%/E8*F8 -> 37800 | G17: =F17*105%/F8*G8 -> 39690 | H17: =G17*105%/G8*H8 -> 83349 | I17: =H17*105%/H8*I8 -> 87516.45
B18: Business Development
B19: Business Development Employee ($1500 per month) | C19: $ | D19: 1500 | E19: =D19*E10*12 -> 36000 | F19: =E19*105%/E10*F10 -> 37800 | G19: =F19*105%/F10*G10 -> 59535 | H19: =G19*105%/G10*H10 -> 62511.75 | I19: =H19*105%/H10*I10 -> 87516.45
B20: Business Development Employee's Commission | C20: $ | E20: =10%*'1-Financial Model'!D15 -> 1308 | F20: =10%*'1-Financial Model'!E15 -> 2877.6 | G20: =10%*'1-Financial Model'!F15 -> 5755.2 | H20: =10%*'1-Financial Model'!G15 -> 8894.4 | I20: =10%*'1-Financial Model'!H15 -> 10725.6 | K20: (3) Assume that Commission is based on 10% of the Hardware Revenue.
B21: Total | E21: =SUM(E19:E20) -> 37308 | F21: =SUM(F19:F20) -> 40677.6 | G21: =SUM(G19:G20) -> 65290.2 | H21: =SUM(H19:H20) -> 71406.15 | I21: =SUM(I19:I20) -> 98242.05
B22: Admin/ Support
B23: Customer Support Employee ($1000 per month) | C23: $ | D23: 1000 | E23: =D23*E12*12 -> 12000 | F23: =E23*105%/E12*F12 -> 12600 | G23: =F23*105%/F12*G12 -> 13230 | H23: =G23*105%/G12*H12 -> 27783 | I23: =H23*105%/H12*I12 -> 29172.15
B24: Total Salaries | C24: $ | E24: =E16+E17+E21+E23 -> 121308 | F24: =F16+F17+F21+F23 -> 128877.6 | G24: =G16+G17+G21+G23 -> 157900.2 | H24: =H16+H17+H21+H23 -> 224212.65 | I24: =I16+I17+I21+I23 -> 258688.88

Sheet 4-BD Scaling 
B2: Year | C2: BD | D2: Expected Lead/BD/Year | E2: Close rate | F2: New Sales
B3: Y1 | C3: 2 | D3: 18 | E3: 0.15 | F3: =C3*D3*E3 -> 5.4
B4: Y2 | C4: 2 | D4: 28 | E4: 0.2 | F4: =C4*D4*E4 -> 11.2
B5: Y3 | C5: 3 | D5: 34 | E5: 0.22 | F5: =C5*D5*E5 -> 22.44
B6: Y4 | C6: 3 | D6: 50 | E6: 0.23 | F6: =C6*D6*E6 -> 34.5
B7: Y5 | C7: 4 | D7: 40 | E7: 0.25 | F7: =C7*D7*E7 -> 40
B8: Total | F8: =SUM(F3:F7) -> 113.54

Sheet 5-NPV IRR
B2: Year | C2: CF | D2: WACC | E2: Discount Factor | F2: NPV
B3: 0 | C3: =-400000 -> -400000 | D3: 0.2 | E3: =1/(1+D3)^B3 -> 1 | F3: =C3*E3 -> -400000
B4: 1 | C4: ='1-Financial Model'!D62 -> -108935 | D4: 0.2 | E4: =1/(1+D4)^B4 -> 0.83333333 | F4: =C4*E4 -> -90779.167
B5: 2 | C5: ='1-Financial Model'!E62 -> 126105.55 | D5: 0.2 | E5: =1/(1+D5)^B5 -> 0.69444444 | F5: =C5*E5 -> 87573.301
B6: 3 | C6: ='1-Financial Model'!F62 -> 422111.85 | D6: 0.2 | E6: =1/(1+D6)^B6 -> 0.5787037 | F6: =C6*E6 -> 244277.69
B7: 4 | C7: ='1-Financial Model'!G62 -> 916434.86 | D7: 0.2 | E7: =1/(1+D7)^B7 -> 0.48225309 | F7: =C7*E7 -> 441953.54
B8: 5 | C8: ='1-Financial Model'!H62 -> 1587004.5 | D8: 0.2 | E8: =1/(1+D8)^B8 -> 0.40187757 | F8: =C8*E8 -> 637781.51
B9: Total NPV | F9: =SUM(F3:F8) -> 920806.87
B11: IRR | C11: =IRR(C3:C8) -> 0.57713142

Sheet 6-Reference
A1: Nursing Institute Report | B1: https://nurse.mohw.gov.tw/mp-2.html
A2: Elderly Instution Report | B2: https://stis.mohw.gov.tw/HWSDweb/common/CommonQuery.aspx?code=G&id=69&utm_source=chatgpt.com
A3: Benchmark for prices | B3: https://www.ncoa.org/product-resources/medical-alert-systems/best-medical-alert-systems-with-fall-detection/?utm_source=chatgpt.com
A4: Nursing homes price/month | B4: https://www.aftygh.gov.tw/english-dep/nursing-home/?utm_source=chatgpt.com https://chnh.mohw.gov.tw/eng/content/index.aspx?Parser=1%2C14%2C95%2C79&utm_source=chatgpt.com https://www.tsmh.org.tw/sites/tsmhcare/fee.html?utm_source=chatgpt.com https://www.paochien.com.tw/twuse/page?pageid=1100005&typeid=1000&utm_source=chatgpt.com https://wwwv.tsgh.ndmutsgh.edu.tw/unit/10071/17981
A5: Nurse call band | B5: https://store.directsupply.com/Product/replacement-wristband-transmitter-tl-4005-door-systems-11023710?quantity=1
